
2023-04-21 15:27:38,096 - INFO - buying power is: 172064.5249503673
2023-04-21 15:27:38,096 - INFO - last trade price is: 27304.5406434
2023-04-21 15:27:38,096 - INFO - holding amount is: 0
2023-04-21 15:31:37,694 - INFO - buying power is: 172064.5249503673
2023-04-21 15:31:37,696 - INFO - last trade price is: 27304.5406434
2023-04-21 15:31:37,696 - INFO - holding amount is: 0
2023-04-21 15:35:10,028 - INFO - Bought 0.6308698620037518 of BTC/USD at price: 27274.171
2023-04-21 15:35:10,121 - INFO - last trade price is: 27274.171
2023-04-21 15:35:24,615 - INFO - Bought in -1s
2023-04-21 15:42:42,173 - INFO - Sold 0.6314630501453006 of BTC/USD at price: 27248.55
2023-04-21 15:42:42,273 - INFO - last trade price is: 27248.55
2023-04-21 15:52:39,858 - INFO - Sold 0.62935923 of BTC/USD at price: 27276.105
2023-04-21 15:52:39,953 - ERROR - Sell Order submission failed
Traceback (most recent call last):
  File "/Users/xinyaoli/PycharmProjects/Alpaca-Test/venv/lib/python3.8/site-packages/alpaca_trade_api/rest.py", line 234, in _one_request
    resp.raise_for_status()
  File "/Users/xinyaoli/PycharmProjects/Alpaca-Test/venv/lib/python3.8/site-packages/requests/models.py", line 1021, in raise_for_status
    raise HTTPError(http_error_msg, response=self)
requests.exceptions.HTTPError: 404 Client Error: Not Found for url: https://paper-api.alpaca.markets/v2/positions/BTCUSD

During handling of the above exception, another exception occurred:

Traceback (most recent call last):
  File "/Users/xinyaoli/PycharmProjects/Alpaca-Test/main.py", line 106, in grid_trading
    self.holding_amount = float(self.api.get_position(ticker_for_holding).qty)
  File "/Users/xinyaoli/PycharmProjects/Alpaca-Test/venv/lib/python3.8/site-packages/alpaca_trade_api/rest.py", line 504, in get_position
    resp = self.get('/positions/{}'.format(symbol))
  File "/Users/xinyaoli/PycharmProjects/Alpaca-Test/venv/lib/python3.8/site-packages/alpaca_trade_api/rest.py", line 250, in get
    return self._request('GET', path, data)
  File "/Users/xinyaoli/PycharmProjects/Alpaca-Test/venv/lib/python3.8/site-packages/alpaca_trade_api/rest.py", line 213, in _request
    return self._one_request(method, url, opts, retry)
  File "/Users/xinyaoli/PycharmProjects/Alpaca-Test/venv/lib/python3.8/site-packages/alpaca_trade_api/rest.py", line 242, in _one_request
    raise APIError(error, http_error)
alpaca_trade_api.rest.APIError: position does not exist
2023-04-21 15:52:39,963 - INFO - last trade price is: 27248.55
2023-04-21 15:52:41,243 - ERROR - Sell Order submission failed
Traceback (most recent call last):
  File "/Users/xinyaoli/PycharmProjects/Alpaca-Test/venv/lib/python3.8/site-packages/alpaca_trade_api/rest.py", line 234, in _one_request
    resp.raise_for_status()
  File "/Users/xinyaoli/PycharmProjects/Alpaca-Test/venv/lib/python3.8/site-packages/requests/models.py", line 1021, in raise_for_status
    raise HTTPError(http_error_msg, response=self)
requests.exceptions.HTTPError: 403 Client Error: Forbidden for url: https://paper-api.alpaca.markets/v2/orders

During handling of the above exception, another exception occurred:

Traceback (most recent call last):
  File "/Users/xinyaoli/PycharmProjects/Alpaca-Test/main.py", line 104, in grid_trading
    self.api.submit_order(ticker, selling_amount, 'sell', 'market', time_in_force='gtc')
  File "/Users/xinyaoli/PycharmProjects/Alpaca-Test/venv/lib/python3.8/site-packages/alpaca_trade_api/rest.py", line 429, in submit_order
    resp = self.post('/orders', params)
  File "/Users/xinyaoli/PycharmProjects/Alpaca-Test/venv/lib/python3.8/site-packages/alpaca_trade_api/rest.py", line 253, in post
    return self._request('POST', path, data)
  File "/Users/xinyaoli/PycharmProjects/Alpaca-Test/venv/lib/python3.8/site-packages/alpaca_trade_api/rest.py", line 213, in _request
    return self._one_request(method, url, opts, retry)
  File "/Users/xinyaoli/PycharmProjects/Alpaca-Test/venv/lib/python3.8/site-packages/alpaca_trade_api/rest.py", line 242, in _one_request
    raise APIError(error, http_error)
alpaca_trade_api.rest.APIError: insufficient balance for BTC (requested: 0.62935923, available: 0)
2023-04-21 15:52:41,245 - INFO - last trade price is: 27248.55
2023-04-21 15:52:42,556 - ERROR - Sell Order submission failed
Traceback (most recent call last):
  File "/Users/xinyaoli/PycharmProjects/Alpaca-Test/venv/lib/python3.8/site-packages/alpaca_trade_api/rest.py", line 234, in _one_request
    resp.raise_for_status()
  File "/Users/xinyaoli/PycharmProjects/Alpaca-Test/venv/lib/python3.8/site-packages/requests/models.py", line 1021, in raise_for_status
    raise HTTPError(http_error_msg, response=self)
requests.exceptions.HTTPError: 403 Client Error: Forbidden for url: https://paper-api.alpaca.markets/v2/orders

During handling of the above exception, another exception occurred:

Traceback (most recent call last):
  File "/Users/xinyaoli/PycharmProjects/Alpaca-Test/main.py", line 104, in grid_trading
    self.api.submit_order(ticker, selling_amount, 'sell', 'market', time_in_force='gtc')
  File "/Users/xinyaoli/PycharmProjects/Alpaca-Test/venv/lib/python3.8/site-packages/alpaca_trade_api/rest.py", line 429, in submit_order
    resp = self.post('/orders', params)
  File "/Users/xinyaoli/PycharmProjects/Alpaca-Test/venv/lib/python3.8/site-packages/alpaca_trade_api/rest.py", line 253, in post
    return self._request('POST', path, data)
  File "/Users/xinyaoli/PycharmProjects/Alpaca-Test/venv/lib/python3.8/site-packages/alpaca_trade_api/rest.py", line 213, in _request
    return self._one_request(method, url, opts, retry)
  File "/Users/xinyaoli/PycharmProjects/Alpaca-Test/venv/lib/python3.8/site-packages/alpaca_trade_api/rest.py", line 242, in _one_request
    raise APIError(error, http_error)
alpaca_trade_api.rest.APIError: insufficient balance for BTC (requested: 0.62935923, available: 0)
2023-04-21 15:52:42,557 - INFO - last trade price is: 27248.55
2023-04-21 16:01:51,924 - ERROR - Sell Order submission failed
Traceback (most recent call last):
  File "/Users/xinyaoli/PycharmProjects/Alpaca-Test/venv/lib/python3.8/site-packages/urllib3/connectionpool.py", line 449, in _make_request
    six.raise_from(e, None)
  File "<string>", line 3, in raise_from
  File "/Users/xinyaoli/PycharmProjects/Alpaca-Test/venv/lib/python3.8/site-packages/urllib3/connectionpool.py", line 444, in _make_request
    httplib_response = conn.getresponse()
  File "/Library/Frameworks/Python.framework/Versions/3.8/lib/python3.8/http/client.py", line 1322, in getresponse
    response.begin()
  File "/Library/Frameworks/Python.framework/Versions/3.8/lib/python3.8/http/client.py", line 303, in begin
    version, status, reason = self._read_status()
  File "/Library/Frameworks/Python.framework/Versions/3.8/lib/python3.8/http/client.py", line 264, in _read_status
    line = str(self.fp.readline(_MAXLINE + 1), "iso-8859-1")
  File "/Library/Frameworks/Python.framework/Versions/3.8/lib/python3.8/socket.py", line 669, in readinto
    return self._sock.recv_into(b)
  File "/Library/Frameworks/Python.framework/Versions/3.8/lib/python3.8/ssl.py", line 1241, in recv_into
    return self.read(nbytes, buffer)
  File "/Library/Frameworks/Python.framework/Versions/3.8/lib/python3.8/ssl.py", line 1099, in read
    return self._sslobj.read(len, buffer)
TimeoutError: [Errno 60] Operation timed out

During handling of the above exception, another exception occurred:

Traceback (most recent call last):
  File "/Users/xinyaoli/PycharmProjects/Alpaca-Test/venv/lib/python3.8/site-packages/requests/adapters.py", line 489, in send
    resp = conn.urlopen(
  File "/Users/xinyaoli/PycharmProjects/Alpaca-Test/venv/lib/python3.8/site-packages/urllib3/connectionpool.py", line 787, in urlopen
    retries = retries.increment(
  File "/Users/xinyaoli/PycharmProjects/Alpaca-Test/venv/lib/python3.8/site-packages/urllib3/util/retry.py", line 550, in increment
    raise six.reraise(type(error), error, _stacktrace)
  File "/Users/xinyaoli/PycharmProjects/Alpaca-Test/venv/lib/python3.8/site-packages/urllib3/packages/six.py", line 770, in reraise
    raise value
  File "/Users/xinyaoli/PycharmProjects/Alpaca-Test/venv/lib/python3.8/site-packages/urllib3/connectionpool.py", line 703, in urlopen
    httplib_response = self._make_request(
  File "/Users/xinyaoli/PycharmProjects/Alpaca-Test/venv/lib/python3.8/site-packages/urllib3/connectionpool.py", line 451, in _make_request
    self._raise_timeout(err=e, url=url, timeout_value=read_timeout)
  File "/Users/xinyaoli/PycharmProjects/Alpaca-Test/venv/lib/python3.8/site-packages/urllib3/connectionpool.py", line 357, in _raise_timeout
    raise ReadTimeoutError(
urllib3.exceptions.ReadTimeoutError: HTTPSConnectionPool(host='paper-api.alpaca.markets', port=443): Read timed out. (read timeout=None)

During handling of the above exception, another exception occurred:

Traceback (most recent call last):
  File "/Users/xinyaoli/PycharmProjects/Alpaca-Test/main.py", line 104, in grid_trading
    self.api.submit_order(ticker, selling_amount, 'sell', 'market', time_in_force='gtc')
  File "/Users/xinyaoli/PycharmProjects/Alpaca-Test/venv/lib/python3.8/site-packages/alpaca_trade_api/rest.py", line 429, in submit_order
    resp = self.post('/orders', params)
  File "/Users/xinyaoli/PycharmProjects/Alpaca-Test/venv/lib/python3.8/site-packages/alpaca_trade_api/rest.py", line 253, in post
    return self._request('POST', path, data)
  File "/Users/xinyaoli/PycharmProjects/Alpaca-Test/venv/lib/python3.8/site-packages/alpaca_trade_api/rest.py", line 213, in _request
    return self._one_request(method, url, opts, retry)
  File "/Users/xinyaoli/PycharmProjects/Alpaca-Test/venv/lib/python3.8/site-packages/alpaca_trade_api/rest.py", line 232, in _one_request
    resp = self._session.request(method, url, **opts)
  File "/Users/xinyaoli/PycharmProjects/Alpaca-Test/venv/lib/python3.8/site-packages/requests/sessions.py", line 587, in request
    resp = self.send(prep, **send_kwargs)
  File "/Users/xinyaoli/PycharmProjects/Alpaca-Test/venv/lib/python3.8/site-packages/requests/sessions.py", line 701, in send
    r = adapter.send(request, **kwargs)
  File "/Users/xinyaoli/PycharmProjects/Alpaca-Test/venv/lib/python3.8/site-packages/requests/adapters.py", line 578, in send
    raise ReadTimeout(e, request=request)
requests.exceptions.ReadTimeout: HTTPSConnectionPool(host='paper-api.alpaca.markets', port=443): Read timed out. (read timeout=None)
2023-04-21 16:01:51,931 - INFO - last trade price is: 27248.55
2023-04-21 16:01:53,485 - ERROR - Sell Order submission failed
Traceback (most recent call last):
  File "/Users/xinyaoli/PycharmProjects/Alpaca-Test/venv/lib/python3.8/site-packages/alpaca_trade_api/rest.py", line 234, in _one_request
    resp.raise_for_status()
  File "/Users/xinyaoli/PycharmProjects/Alpaca-Test/venv/lib/python3.8/site-packages/requests/models.py", line 1021, in raise_for_status
    raise HTTPError(http_error_msg, response=self)
requests.exceptions.HTTPError: 403 Client Error: Forbidden for url: https://paper-api.alpaca.markets/v2/orders

During handling of the above exception, another exception occurred:

Traceback (most recent call last):
  File "/Users/xinyaoli/PycharmProjects/Alpaca-Test/main.py", line 104, in grid_trading
    self.api.submit_order(ticker, selling_amount, 'sell', 'market', time_in_force='gtc')
  File "/Users/xinyaoli/PycharmProjects/Alpaca-Test/venv/lib/python3.8/site-packages/alpaca_trade_api/rest.py", line 429, in submit_order
    resp = self.post('/orders', params)
  File "/Users/xinyaoli/PycharmProjects/Alpaca-Test/venv/lib/python3.8/site-packages/alpaca_trade_api/rest.py", line 253, in post
    return self._request('POST', path, data)
  File "/Users/xinyaoli/PycharmProjects/Alpaca-Test/venv/lib/python3.8/site-packages/alpaca_trade_api/rest.py", line 213, in _request
    return self._one_request(method, url, opts, retry)
  File "/Users/xinyaoli/PycharmProjects/Alpaca-Test/venv/lib/python3.8/site-packages/alpaca_trade_api/rest.py", line 242, in _one_request
    raise APIError(error, http_error)
alpaca_trade_api.rest.APIError: insufficient balance for BTC (requested: 0.62935923, available: 0)
2023-04-21 16:01:53,487 - INFO - last trade price is: 27248.55
2023-04-21 16:01:54,796 - ERROR - Sell Order submission failed
Traceback (most recent call last):
  File "/Users/xinyaoli/PycharmProjects/Alpaca-Test/venv/lib/python3.8/site-packages/alpaca_trade_api/rest.py", line 234, in _one_request
    resp.raise_for_status()
  File "/Users/xinyaoli/PycharmProjects/Alpaca-Test/venv/lib/python3.8/site-packages/requests/models.py", line 1021, in raise_for_status
    raise HTTPError(http_error_msg, response=self)
requests.exceptions.HTTPError: 403 Client Error: Forbidden for url: https://paper-api.alpaca.markets/v2/orders

During handling of the above exception, another exception occurred:

Traceback (most recent call last):
  File "/Users/xinyaoli/PycharmProjects/Alpaca-Test/main.py", line 104, in grid_trading
    self.api.submit_order(ticker, selling_amount, 'sell', 'market', time_in_force='gtc')
  File "/Users/xinyaoli/PycharmProjects/Alpaca-Test/venv/lib/python3.8/site-packages/alpaca_trade_api/rest.py", line 429, in submit_order
    resp = self.post('/orders', params)
  File "/Users/xinyaoli/PycharmProjects/Alpaca-Test/venv/lib/python3.8/site-packages/alpaca_trade_api/rest.py", line 253, in post
    return self._request('POST', path, data)
  File "/Users/xinyaoli/PycharmProjects/Alpaca-Test/venv/lib/python3.8/site-packages/alpaca_trade_api/rest.py", line 213, in _request
    return self._one_request(method, url, opts, retry)
  File "/Users/xinyaoli/PycharmProjects/Alpaca-Test/venv/lib/python3.8/site-packages/alpaca_trade_api/rest.py", line 242, in _one_request
    raise APIError(error, http_error)
alpaca_trade_api.rest.APIError: insufficient balance for BTC (requested: 0.62935923, available: 0)
2023-04-21 16:01:54,798 - INFO - last trade price is: 27248.55
2023-04-21 16:01:56,107 - ERROR - Sell Order submission failed
Traceback (most recent call last):
  File "/Users/xinyaoli/PycharmProjects/Alpaca-Test/venv/lib/python3.8/site-packages/alpaca_trade_api/rest.py", line 234, in _one_request
    resp.raise_for_status()
  File "/Users/xinyaoli/PycharmProjects/Alpaca-Test/venv/lib/python3.8/site-packages/requests/models.py", line 1021, in raise_for_status
    raise HTTPError(http_error_msg, response=self)
requests.exceptions.HTTPError: 403 Client Error: Forbidden for url: https://paper-api.alpaca.markets/v2/orders

During handling of the above exception, another exception occurred:

Traceback (most recent call last):
  File "/Users/xinyaoli/PycharmProjects/Alpaca-Test/main.py", line 104, in grid_trading
    self.api.submit_order(ticker, selling_amount, 'sell', 'market', time_in_force='gtc')
  File "/Users/xinyaoli/PycharmProjects/Alpaca-Test/venv/lib/python3.8/site-packages/alpaca_trade_api/rest.py", line 429, in submit_order
    resp = self.post('/orders', params)
  File "/Users/xinyaoli/PycharmProjects/Alpaca-Test/venv/lib/python3.8/site-packages/alpaca_trade_api/rest.py", line 253, in post
    return self._request('POST', path, data)
  File "/Users/xinyaoli/PycharmProjects/Alpaca-Test/venv/lib/python3.8/site-packages/alpaca_trade_api/rest.py", line 213, in _request
    return self._one_request(method, url, opts, retry)
  File "/Users/xinyaoli/PycharmProjects/Alpaca-Test/venv/lib/python3.8/site-packages/alpaca_trade_api/rest.py", line 242, in _one_request
    raise APIError(error, http_error)
alpaca_trade_api.rest.APIError: insufficient balance for BTC (requested: 0.62935923, available: 0)
2023-04-21 16:01:56,108 - INFO - last trade price is: 27248.55
2023-04-21 16:02:00,992 - ERROR - Sell Order submission failed
Traceback (most recent call last):
  File "/Users/xinyaoli/PycharmProjects/Alpaca-Test/venv/lib/python3.8/site-packages/alpaca_trade_api/rest.py", line 234, in _one_request
    resp.raise_for_status()
  File "/Users/xinyaoli/PycharmProjects/Alpaca-Test/venv/lib/python3.8/site-packages/requests/models.py", line 1021, in raise_for_status
    raise HTTPError(http_error_msg, response=self)
requests.exceptions.HTTPError: 403 Client Error: Forbidden for url: https://paper-api.alpaca.markets/v2/orders

During handling of the above exception, another exception occurred:

Traceback (most recent call last):
  File "/Users/xinyaoli/PycharmProjects/Alpaca-Test/main.py", line 104, in grid_trading
    self.api.submit_order(ticker, selling_amount, 'sell', 'market', time_in_force='gtc')
  File "/Users/xinyaoli/PycharmProjects/Alpaca-Test/venv/lib/python3.8/site-packages/alpaca_trade_api/rest.py", line 429, in submit_order
    resp = self.post('/orders', params)
  File "/Users/xinyaoli/PycharmProjects/Alpaca-Test/venv/lib/python3.8/site-packages/alpaca_trade_api/rest.py", line 253, in post
    return self._request('POST', path, data)
  File "/Users/xinyaoli/PycharmProjects/Alpaca-Test/venv/lib/python3.8/site-packages/alpaca_trade_api/rest.py", line 213, in _request
    return self._one_request(method, url, opts, retry)
  File "/Users/xinyaoli/PycharmProjects/Alpaca-Test/venv/lib/python3.8/site-packages/alpaca_trade_api/rest.py", line 242, in _one_request
    raise APIError(error, http_error)
alpaca_trade_api.rest.APIError: insufficient balance for BTC (requested: 0.62935923, available: 0)
2023-04-21 16:02:00,994 - INFO - last trade price is: 27248.55
2023-04-21 16:02:02,293 - ERROR - Sell Order submission failed
Traceback (most recent call last):
  File "/Users/xinyaoli/PycharmProjects/Alpaca-Test/venv/lib/python3.8/site-packages/alpaca_trade_api/rest.py", line 234, in _one_request
    resp.raise_for_status()
  File "/Users/xinyaoli/PycharmProjects/Alpaca-Test/venv/lib/python3.8/site-packages/requests/models.py", line 1021, in raise_for_status
    raise HTTPError(http_error_msg, response=self)
requests.exceptions.HTTPError: 403 Client Error: Forbidden for url: https://paper-api.alpaca.markets/v2/orders

During handling of the above exception, another exception occurred:

Traceback (most recent call last):
  File "/Users/xinyaoli/PycharmProjects/Alpaca-Test/main.py", line 104, in grid_trading
    self.api.submit_order(ticker, selling_amount, 'sell', 'market', time_in_force='gtc')
  File "/Users/xinyaoli/PycharmProjects/Alpaca-Test/venv/lib/python3.8/site-packages/alpaca_trade_api/rest.py", line 429, in submit_order
    resp = self.post('/orders', params)
  File "/Users/xinyaoli/PycharmProjects/Alpaca-Test/venv/lib/python3.8/site-packages/alpaca_trade_api/rest.py", line 253, in post
    return self._request('POST', path, data)
  File "/Users/xinyaoli/PycharmProjects/Alpaca-Test/venv/lib/python3.8/site-packages/alpaca_trade_api/rest.py", line 213, in _request
    return self._one_request(method, url, opts, retry)
  File "/Users/xinyaoli/PycharmProjects/Alpaca-Test/venv/lib/python3.8/site-packages/alpaca_trade_api/rest.py", line 242, in _one_request
    raise APIError(error, http_error)
alpaca_trade_api.rest.APIError: insufficient balance for BTC (requested: 0.62935923, available: 0)
2023-04-21 16:02:02,294 - INFO - last trade price is: 27248.55
2023-04-21 16:02:03,614 - ERROR - Sell Order submission failed
Traceback (most recent call last):
  File "/Users/xinyaoli/PycharmProjects/Alpaca-Test/venv/lib/python3.8/site-packages/alpaca_trade_api/rest.py", line 234, in _one_request
    resp.raise_for_status()
  File "/Users/xinyaoli/PycharmProjects/Alpaca-Test/venv/lib/python3.8/site-packages/requests/models.py", line 1021, in raise_for_status
    raise HTTPError(http_error_msg, response=self)
requests.exceptions.HTTPError: 403 Client Error: Forbidden for url: https://paper-api.alpaca.markets/v2/orders

During handling of the above exception, another exception occurred:

Traceback (most recent call last):
  File "/Users/xinyaoli/PycharmProjects/Alpaca-Test/main.py", line 104, in grid_trading
    self.api.submit_order(ticker, selling_amount, 'sell', 'market', time_in_force='gtc')
  File "/Users/xinyaoli/PycharmProjects/Alpaca-Test/venv/lib/python3.8/site-packages/alpaca_trade_api/rest.py", line 429, in submit_order
    resp = self.post('/orders', params)
  File "/Users/xinyaoli/PycharmProjects/Alpaca-Test/venv/lib/python3.8/site-packages/alpaca_trade_api/rest.py", line 253, in post
    return self._request('POST', path, data)
  File "/Users/xinyaoli/PycharmProjects/Alpaca-Test/venv/lib/python3.8/site-packages/alpaca_trade_api/rest.py", line 213, in _request
    return self._one_request(method, url, opts, retry)
  File "/Users/xinyaoli/PycharmProjects/Alpaca-Test/venv/lib/python3.8/site-packages/alpaca_trade_api/rest.py", line 242, in _one_request
    raise APIError(error, http_error)
alpaca_trade_api.rest.APIError: insufficient balance for BTC (requested: 0.62935923, available: 0)
2023-04-21 16:02:03,614 - INFO - last trade price is: 27248.55
2023-04-21 16:02:44,313 - ERROR - Sell Order submission failed
Traceback (most recent call last):
  File "/Users/xinyaoli/PycharmProjects/Alpaca-Test/venv/lib/python3.8/site-packages/alpaca_trade_api/rest.py", line 234, in _one_request
    resp.raise_for_status()
  File "/Users/xinyaoli/PycharmProjects/Alpaca-Test/venv/lib/python3.8/site-packages/requests/models.py", line 1021, in raise_for_status
    raise HTTPError(http_error_msg, response=self)
requests.exceptions.HTTPError: 403 Client Error: Forbidden for url: https://paper-api.alpaca.markets/v2/orders

During handling of the above exception, another exception occurred:

Traceback (most recent call last):
  File "/Users/xinyaoli/PycharmProjects/Alpaca-Test/main.py", line 104, in grid_trading
    self.api.submit_order(ticker, selling_amount, 'sell', 'market', time_in_force='gtc')
  File "/Users/xinyaoli/PycharmProjects/Alpaca-Test/venv/lib/python3.8/site-packages/alpaca_trade_api/rest.py", line 429, in submit_order
    resp = self.post('/orders', params)
  File "/Users/xinyaoli/PycharmProjects/Alpaca-Test/venv/lib/python3.8/site-packages/alpaca_trade_api/rest.py", line 253, in post
    return self._request('POST', path, data)
  File "/Users/xinyaoli/PycharmProjects/Alpaca-Test/venv/lib/python3.8/site-packages/alpaca_trade_api/rest.py", line 213, in _request
    return self._one_request(method, url, opts, retry)
  File "/Users/xinyaoli/PycharmProjects/Alpaca-Test/venv/lib/python3.8/site-packages/alpaca_trade_api/rest.py", line 242, in _one_request
    raise APIError(error, http_error)
alpaca_trade_api.rest.APIError: insufficient balance for BTC (requested: 0.62935923, available: 0)
2023-04-21 16:02:44,315 - INFO - last trade price is: 27248.55
2023-04-21 16:02:45,607 - ERROR - Sell Order submission failed
Traceback (most recent call last):
  File "/Users/xinyaoli/PycharmProjects/Alpaca-Test/venv/lib/python3.8/site-packages/alpaca_trade_api/rest.py", line 234, in _one_request
    resp.raise_for_status()
  File "/Users/xinyaoli/PycharmProjects/Alpaca-Test/venv/lib/python3.8/site-packages/requests/models.py", line 1021, in raise_for_status
    raise HTTPError(http_error_msg, response=self)
requests.exceptions.HTTPError: 403 Client Error: Forbidden for url: https://paper-api.alpaca.markets/v2/orders

During handling of the above exception, another exception occurred:

Traceback (most recent call last):
  File "/Users/xinyaoli/PycharmProjects/Alpaca-Test/main.py", line 104, in grid_trading
    self.api.submit_order(ticker, selling_amount, 'sell', 'market', time_in_force='gtc')
  File "/Users/xinyaoli/PycharmProjects/Alpaca-Test/venv/lib/python3.8/site-packages/alpaca_trade_api/rest.py", line 429, in submit_order
    resp = self.post('/orders', params)
  File "/Users/xinyaoli/PycharmProjects/Alpaca-Test/venv/lib/python3.8/site-packages/alpaca_trade_api/rest.py", line 253, in post
    return self._request('POST', path, data)
  File "/Users/xinyaoli/PycharmProjects/Alpaca-Test/venv/lib/python3.8/site-packages/alpaca_trade_api/rest.py", line 213, in _request
    return self._one_request(method, url, opts, retry)
  File "/Users/xinyaoli/PycharmProjects/Alpaca-Test/venv/lib/python3.8/site-packages/alpaca_trade_api/rest.py", line 242, in _one_request
    raise APIError(error, http_error)
alpaca_trade_api.rest.APIError: insufficient balance for BTC (requested: 0.62935923, available: 0)
2023-04-21 16:02:45,608 - INFO - last trade price is: 27248.55
2023-04-21 16:02:46,897 - ERROR - Sell Order submission failed
Traceback (most recent call last):
  File "/Users/xinyaoli/PycharmProjects/Alpaca-Test/venv/lib/python3.8/site-packages/alpaca_trade_api/rest.py", line 234, in _one_request
    resp.raise_for_status()
  File "/Users/xinyaoli/PycharmProjects/Alpaca-Test/venv/lib/python3.8/site-packages/requests/models.py", line 1021, in raise_for_status
    raise HTTPError(http_error_msg, response=self)
requests.exceptions.HTTPError: 403 Client Error: Forbidden for url: https://paper-api.alpaca.markets/v2/orders

During handling of the above exception, another exception occurred:

Traceback (most recent call last):
  File "/Users/xinyaoli/PycharmProjects/Alpaca-Test/main.py", line 104, in grid_trading
    self.api.submit_order(ticker, selling_amount, 'sell', 'market', time_in_force='gtc')
  File "/Users/xinyaoli/PycharmProjects/Alpaca-Test/venv/lib/python3.8/site-packages/alpaca_trade_api/rest.py", line 429, in submit_order
    resp = self.post('/orders', params)
  File "/Users/xinyaoli/PycharmProjects/Alpaca-Test/venv/lib/python3.8/site-packages/alpaca_trade_api/rest.py", line 253, in post
    return self._request('POST', path, data)
  File "/Users/xinyaoli/PycharmProjects/Alpaca-Test/venv/lib/python3.8/site-packages/alpaca_trade_api/rest.py", line 213, in _request
    return self._one_request(method, url, opts, retry)
  File "/Users/xinyaoli/PycharmProjects/Alpaca-Test/venv/lib/python3.8/site-packages/alpaca_trade_api/rest.py", line 242, in _one_request
    raise APIError(error, http_error)
alpaca_trade_api.rest.APIError: insufficient balance for BTC (requested: 0.62935923, available: 0)
2023-04-21 16:02:46,898 - INFO - last trade price is: 27248.55
2023-04-21 16:02:48,199 - ERROR - Sell Order submission failed
Traceback (most recent call last):
  File "/Users/xinyaoli/PycharmProjects/Alpaca-Test/venv/lib/python3.8/site-packages/alpaca_trade_api/rest.py", line 234, in _one_request
    resp.raise_for_status()
  File "/Users/xinyaoli/PycharmProjects/Alpaca-Test/venv/lib/python3.8/site-packages/requests/models.py", line 1021, in raise_for_status
    raise HTTPError(http_error_msg, response=self)
requests.exceptions.HTTPError: 403 Client Error: Forbidden for url: https://paper-api.alpaca.markets/v2/orders

During handling of the above exception, another exception occurred:

Traceback (most recent call last):
  File "/Users/xinyaoli/PycharmProjects/Alpaca-Test/main.py", line 104, in grid_trading
    self.api.submit_order(ticker, selling_amount, 'sell', 'market', time_in_force='gtc')
  File "/Users/xinyaoli/PycharmProjects/Alpaca-Test/venv/lib/python3.8/site-packages/alpaca_trade_api/rest.py", line 429, in submit_order
    resp = self.post('/orders', params)
  File "/Users/xinyaoli/PycharmProjects/Alpaca-Test/venv/lib/python3.8/site-packages/alpaca_trade_api/rest.py", line 253, in post
    return self._request('POST', path, data)
  File "/Users/xinyaoli/PycharmProjects/Alpaca-Test/venv/lib/python3.8/site-packages/alpaca_trade_api/rest.py", line 213, in _request
    return self._one_request(method, url, opts, retry)
  File "/Users/xinyaoli/PycharmProjects/Alpaca-Test/venv/lib/python3.8/site-packages/alpaca_trade_api/rest.py", line 242, in _one_request
    raise APIError(error, http_error)
alpaca_trade_api.rest.APIError: insufficient balance for BTC (requested: 0.62935923, available: 0)
2023-04-21 16:02:48,201 - INFO - last trade price is: 27248.55
2023-04-21 16:03:10,881 - ERROR - Sell Order submission failed
Traceback (most recent call last):
  File "/Users/xinyaoli/PycharmProjects/Alpaca-Test/venv/lib/python3.8/site-packages/alpaca_trade_api/rest.py", line 234, in _one_request
    resp.raise_for_status()
  File "/Users/xinyaoli/PycharmProjects/Alpaca-Test/venv/lib/python3.8/site-packages/requests/models.py", line 1021, in raise_for_status
    raise HTTPError(http_error_msg, response=self)
requests.exceptions.HTTPError: 403 Client Error: Forbidden for url: https://paper-api.alpaca.markets/v2/orders

During handling of the above exception, another exception occurred:

Traceback (most recent call last):
  File "/Users/xinyaoli/PycharmProjects/Alpaca-Test/main.py", line 104, in grid_trading
    self.api.submit_order(ticker, selling_amount, 'sell', 'market', time_in_force='gtc')
  File "/Users/xinyaoli/PycharmProjects/Alpaca-Test/venv/lib/python3.8/site-packages/alpaca_trade_api/rest.py", line 429, in submit_order
    resp = self.post('/orders', params)
  File "/Users/xinyaoli/PycharmProjects/Alpaca-Test/venv/lib/python3.8/site-packages/alpaca_trade_api/rest.py", line 253, in post
    return self._request('POST', path, data)
  File "/Users/xinyaoli/PycharmProjects/Alpaca-Test/venv/lib/python3.8/site-packages/alpaca_trade_api/rest.py", line 213, in _request
    return self._one_request(method, url, opts, retry)
  File "/Users/xinyaoli/PycharmProjects/Alpaca-Test/venv/lib/python3.8/site-packages/alpaca_trade_api/rest.py", line 242, in _one_request
    raise APIError(error, http_error)
alpaca_trade_api.rest.APIError: insufficient balance for BTC (requested: 0.62935923, available: 0)
2023-04-21 16:03:10,884 - INFO - last trade price is: 27248.55
2023-04-21 16:03:12,171 - ERROR - Sell Order submission failed
Traceback (most recent call last):
  File "/Users/xinyaoli/PycharmProjects/Alpaca-Test/venv/lib/python3.8/site-packages/alpaca_trade_api/rest.py", line 234, in _one_request
    resp.raise_for_status()
  File "/Users/xinyaoli/PycharmProjects/Alpaca-Test/venv/lib/python3.8/site-packages/requests/models.py", line 1021, in raise_for_status
    raise HTTPError(http_error_msg, response=self)
requests.exceptions.HTTPError: 403 Client Error: Forbidden for url: https://paper-api.alpaca.markets/v2/orders

During handling of the above exception, another exception occurred:

Traceback (most recent call last):
  File "/Users/xinyaoli/PycharmProjects/Alpaca-Test/main.py", line 104, in grid_trading
    self.api.submit_order(ticker, selling_amount, 'sell', 'market', time_in_force='gtc')
  File "/Users/xinyaoli/PycharmProjects/Alpaca-Test/venv/lib/python3.8/site-packages/alpaca_trade_api/rest.py", line 429, in submit_order
    resp = self.post('/orders', params)
  File "/Users/xinyaoli/PycharmProjects/Alpaca-Test/venv/lib/python3.8/site-packages/alpaca_trade_api/rest.py", line 253, in post
    return self._request('POST', path, data)
  File "/Users/xinyaoli/PycharmProjects/Alpaca-Test/venv/lib/python3.8/site-packages/alpaca_trade_api/rest.py", line 213, in _request
    return self._one_request(method, url, opts, retry)
  File "/Users/xinyaoli/PycharmProjects/Alpaca-Test/venv/lib/python3.8/site-packages/alpaca_trade_api/rest.py", line 242, in _one_request
    raise APIError(error, http_error)
alpaca_trade_api.rest.APIError: insufficient balance for BTC (requested: 0.62935923, available: 0)
2023-04-21 16:03:12,171 - INFO - last trade price is: 27248.55
2023-04-21 16:03:13,455 - ERROR - Sell Order submission failed
Traceback (most recent call last):
  File "/Users/xinyaoli/PycharmProjects/Alpaca-Test/venv/lib/python3.8/site-packages/alpaca_trade_api/rest.py", line 234, in _one_request
    resp.raise_for_status()
  File "/Users/xinyaoli/PycharmProjects/Alpaca-Test/venv/lib/python3.8/site-packages/requests/models.py", line 1021, in raise_for_status
    raise HTTPError(http_error_msg, response=self)
requests.exceptions.HTTPError: 403 Client Error: Forbidden for url: https://paper-api.alpaca.markets/v2/orders

During handling of the above exception, another exception occurred:

Traceback (most recent call last):
  File "/Users/xinyaoli/PycharmProjects/Alpaca-Test/main.py", line 104, in grid_trading
    self.api.submit_order(ticker, selling_amount, 'sell', 'market', time_in_force='gtc')
  File "/Users/xinyaoli/PycharmProjects/Alpaca-Test/venv/lib/python3.8/site-packages/alpaca_trade_api/rest.py", line 429, in submit_order
    resp = self.post('/orders', params)
  File "/Users/xinyaoli/PycharmProjects/Alpaca-Test/venv/lib/python3.8/site-packages/alpaca_trade_api/rest.py", line 253, in post
    return self._request('POST', path, data)
  File "/Users/xinyaoli/PycharmProjects/Alpaca-Test/venv/lib/python3.8/site-packages/alpaca_trade_api/rest.py", line 213, in _request
    return self._one_request(method, url, opts, retry)
  File "/Users/xinyaoli/PycharmProjects/Alpaca-Test/venv/lib/python3.8/site-packages/alpaca_trade_api/rest.py", line 242, in _one_request
    raise APIError(error, http_error)
alpaca_trade_api.rest.APIError: insufficient balance for BTC (requested: 0.62935923, available: 0)
2023-04-21 16:03:13,456 - INFO - last trade price is: 27248.55
2023-04-21 16:03:24,355 - ERROR - Sell Order submission failed
Traceback (most recent call last):
  File "/Users/xinyaoli/PycharmProjects/Alpaca-Test/venv/lib/python3.8/site-packages/alpaca_trade_api/rest.py", line 234, in _one_request
    resp.raise_for_status()
  File "/Users/xinyaoli/PycharmProjects/Alpaca-Test/venv/lib/python3.8/site-packages/requests/models.py", line 1021, in raise_for_status
    raise HTTPError(http_error_msg, response=self)
requests.exceptions.HTTPError: 403 Client Error: Forbidden for url: https://paper-api.alpaca.markets/v2/orders

During handling of the above exception, another exception occurred:

Traceback (most recent call last):
  File "/Users/xinyaoli/PycharmProjects/Alpaca-Test/main.py", line 104, in grid_trading
    self.api.submit_order(ticker, selling_amount, 'sell', 'market', time_in_force='gtc')
  File "/Users/xinyaoli/PycharmProjects/Alpaca-Test/venv/lib/python3.8/site-packages/alpaca_trade_api/rest.py", line 429, in submit_order
    resp = self.post('/orders', params)
  File "/Users/xinyaoli/PycharmProjects/Alpaca-Test/venv/lib/python3.8/site-packages/alpaca_trade_api/rest.py", line 253, in post
    return self._request('POST', path, data)
  File "/Users/xinyaoli/PycharmProjects/Alpaca-Test/venv/lib/python3.8/site-packages/alpaca_trade_api/rest.py", line 213, in _request
    return self._one_request(method, url, opts, retry)
  File "/Users/xinyaoli/PycharmProjects/Alpaca-Test/venv/lib/python3.8/site-packages/alpaca_trade_api/rest.py", line 242, in _one_request
    raise APIError(error, http_error)
alpaca_trade_api.rest.APIError: insufficient balance for BTC (requested: 0.62935923, available: 0)
2023-04-21 16:03:24,357 - INFO - last trade price is: 27248.55
2023-04-21 16:03:25,646 - ERROR - Sell Order submission failed
Traceback (most recent call last):
  File "/Users/xinyaoli/PycharmProjects/Alpaca-Test/venv/lib/python3.8/site-packages/alpaca_trade_api/rest.py", line 234, in _one_request
    resp.raise_for_status()
  File "/Users/xinyaoli/PycharmProjects/Alpaca-Test/venv/lib/python3.8/site-packages/requests/models.py", line 1021, in raise_for_status
    raise HTTPError(http_error_msg, response=self)
requests.exceptions.HTTPError: 403 Client Error: Forbidden for url: https://paper-api.alpaca.markets/v2/orders

During handling of the above exception, another exception occurred:

Traceback (most recent call last):
  File "/Users/xinyaoli/PycharmProjects/Alpaca-Test/main.py", line 104, in grid_trading
    self.api.submit_order(ticker, selling_amount, 'sell', 'market', time_in_force='gtc')
  File "/Users/xinyaoli/PycharmProjects/Alpaca-Test/venv/lib/python3.8/site-packages/alpaca_trade_api/rest.py", line 429, in submit_order
    resp = self.post('/orders', params)
  File "/Users/xinyaoli/PycharmProjects/Alpaca-Test/venv/lib/python3.8/site-packages/alpaca_trade_api/rest.py", line 253, in post
    return self._request('POST', path, data)
  File "/Users/xinyaoli/PycharmProjects/Alpaca-Test/venv/lib/python3.8/site-packages/alpaca_trade_api/rest.py", line 213, in _request
    return self._one_request(method, url, opts, retry)
  File "/Users/xinyaoli/PycharmProjects/Alpaca-Test/venv/lib/python3.8/site-packages/alpaca_trade_api/rest.py", line 242, in _one_request
    raise APIError(error, http_error)
alpaca_trade_api.rest.APIError: insufficient balance for BTC (requested: 0.62935923, available: 0)
2023-04-21 16:03:25,647 - INFO - last trade price is: 27248.55
2023-04-21 16:03:26,927 - ERROR - Sell Order submission failed
Traceback (most recent call last):
  File "/Users/xinyaoli/PycharmProjects/Alpaca-Test/venv/lib/python3.8/site-packages/alpaca_trade_api/rest.py", line 234, in _one_request
    resp.raise_for_status()
  File "/Users/xinyaoli/PycharmProjects/Alpaca-Test/venv/lib/python3.8/site-packages/requests/models.py", line 1021, in raise_for_status
    raise HTTPError(http_error_msg, response=self)
requests.exceptions.HTTPError: 403 Client Error: Forbidden for url: https://paper-api.alpaca.markets/v2/orders

During handling of the above exception, another exception occurred:

Traceback (most recent call last):
  File "/Users/xinyaoli/PycharmProjects/Alpaca-Test/main.py", line 104, in grid_trading
    self.api.submit_order(ticker, selling_amount, 'sell', 'market', time_in_force='gtc')
  File "/Users/xinyaoli/PycharmProjects/Alpaca-Test/venv/lib/python3.8/site-packages/alpaca_trade_api/rest.py", line 429, in submit_order
    resp = self.post('/orders', params)
  File "/Users/xinyaoli/PycharmProjects/Alpaca-Test/venv/lib/python3.8/site-packages/alpaca_trade_api/rest.py", line 253, in post
    return self._request('POST', path, data)
  File "/Users/xinyaoli/PycharmProjects/Alpaca-Test/venv/lib/python3.8/site-packages/alpaca_trade_api/rest.py", line 213, in _request
    return self._one_request(method, url, opts, retry)
  File "/Users/xinyaoli/PycharmProjects/Alpaca-Test/venv/lib/python3.8/site-packages/alpaca_trade_api/rest.py", line 242, in _one_request
    raise APIError(error, http_error)
alpaca_trade_api.rest.APIError: insufficient balance for BTC (requested: 0.62935923, available: 0)
2023-04-21 16:03:26,928 - INFO - last trade price is: 27248.55
2023-04-21 16:03:28,220 - ERROR - Sell Order submission failed
Traceback (most recent call last):
  File "/Users/xinyaoli/PycharmProjects/Alpaca-Test/venv/lib/python3.8/site-packages/alpaca_trade_api/rest.py", line 234, in _one_request
    resp.raise_for_status()
  File "/Users/xinyaoli/PycharmProjects/Alpaca-Test/venv/lib/python3.8/site-packages/requests/models.py", line 1021, in raise_for_status
    raise HTTPError(http_error_msg, response=self)
requests.exceptions.HTTPError: 403 Client Error: Forbidden for url: https://paper-api.alpaca.markets/v2/orders

During handling of the above exception, another exception occurred:

Traceback (most recent call last):
  File "/Users/xinyaoli/PycharmProjects/Alpaca-Test/main.py", line 104, in grid_trading
    self.api.submit_order(ticker, selling_amount, 'sell', 'market', time_in_force='gtc')
  File "/Users/xinyaoli/PycharmProjects/Alpaca-Test/venv/lib/python3.8/site-packages/alpaca_trade_api/rest.py", line 429, in submit_order
    resp = self.post('/orders', params)
  File "/Users/xinyaoli/PycharmProjects/Alpaca-Test/venv/lib/python3.8/site-packages/alpaca_trade_api/rest.py", line 253, in post
    return self._request('POST', path, data)
  File "/Users/xinyaoli/PycharmProjects/Alpaca-Test/venv/lib/python3.8/site-packages/alpaca_trade_api/rest.py", line 213, in _request
    return self._one_request(method, url, opts, retry)
  File "/Users/xinyaoli/PycharmProjects/Alpaca-Test/venv/lib/python3.8/site-packages/alpaca_trade_api/rest.py", line 242, in _one_request
    raise APIError(error, http_error)
alpaca_trade_api.rest.APIError: insufficient balance for BTC (requested: 0.62935923, available: 0)
2023-04-21 16:03:28,231 - INFO - last trade price is: 27248.55
2023-04-21 16:03:29,511 - ERROR - Sell Order submission failed
Traceback (most recent call last):
  File "/Users/xinyaoli/PycharmProjects/Alpaca-Test/venv/lib/python3.8/site-packages/alpaca_trade_api/rest.py", line 234, in _one_request
    resp.raise_for_status()
  File "/Users/xinyaoli/PycharmProjects/Alpaca-Test/venv/lib/python3.8/site-packages/requests/models.py", line 1021, in raise_for_status
    raise HTTPError(http_error_msg, response=self)
requests.exceptions.HTTPError: 403 Client Error: Forbidden for url: https://paper-api.alpaca.markets/v2/orders

During handling of the above exception, another exception occurred:

Traceback (most recent call last):
  File "/Users/xinyaoli/PycharmProjects/Alpaca-Test/main.py", line 104, in grid_trading
    self.api.submit_order(ticker, selling_amount, 'sell', 'market', time_in_force='gtc')
  File "/Users/xinyaoli/PycharmProjects/Alpaca-Test/venv/lib/python3.8/site-packages/alpaca_trade_api/rest.py", line 429, in submit_order
    resp = self.post('/orders', params)
  File "/Users/xinyaoli/PycharmProjects/Alpaca-Test/venv/lib/python3.8/site-packages/alpaca_trade_api/rest.py", line 253, in post
    return self._request('POST', path, data)
  File "/Users/xinyaoli/PycharmProjects/Alpaca-Test/venv/lib/python3.8/site-packages/alpaca_trade_api/rest.py", line 213, in _request
    return self._one_request(method, url, opts, retry)
  File "/Users/xinyaoli/PycharmProjects/Alpaca-Test/venv/lib/python3.8/site-packages/alpaca_trade_api/rest.py", line 242, in _one_request
    raise APIError(error, http_error)
alpaca_trade_api.rest.APIError: insufficient balance for BTC (requested: 0.62935923, available: 0)
2023-04-21 16:03:29,513 - INFO - last trade price is: 27248.55
2023-04-21 16:03:30,791 - ERROR - Sell Order submission failed
Traceback (most recent call last):
  File "/Users/xinyaoli/PycharmProjects/Alpaca-Test/venv/lib/python3.8/site-packages/alpaca_trade_api/rest.py", line 234, in _one_request
    resp.raise_for_status()
  File "/Users/xinyaoli/PycharmProjects/Alpaca-Test/venv/lib/python3.8/site-packages/requests/models.py", line 1021, in raise_for_status
    raise HTTPError(http_error_msg, response=self)
requests.exceptions.HTTPError: 403 Client Error: Forbidden for url: https://paper-api.alpaca.markets/v2/orders

During handling of the above exception, another exception occurred:

Traceback (most recent call last):
  File "/Users/xinyaoli/PycharmProjects/Alpaca-Test/main.py", line 104, in grid_trading
    self.api.submit_order(ticker, selling_amount, 'sell', 'market', time_in_force='gtc')
  File "/Users/xinyaoli/PycharmProjects/Alpaca-Test/venv/lib/python3.8/site-packages/alpaca_trade_api/rest.py", line 429, in submit_order
    resp = self.post('/orders', params)
  File "/Users/xinyaoli/PycharmProjects/Alpaca-Test/venv/lib/python3.8/site-packages/alpaca_trade_api/rest.py", line 253, in post
    return self._request('POST', path, data)
  File "/Users/xinyaoli/PycharmProjects/Alpaca-Test/venv/lib/python3.8/site-packages/alpaca_trade_api/rest.py", line 213, in _request
    return self._one_request(method, url, opts, retry)
  File "/Users/xinyaoli/PycharmProjects/Alpaca-Test/venv/lib/python3.8/site-packages/alpaca_trade_api/rest.py", line 242, in _one_request
    raise APIError(error, http_error)
alpaca_trade_api.rest.APIError: insufficient balance for BTC (requested: 0.62935923, available: 0)
2023-04-21 16:03:30,793 - INFO - last trade price is: 27248.55
2023-04-21 16:03:32,082 - ERROR - Sell Order submission failed
Traceback (most recent call last):
  File "/Users/xinyaoli/PycharmProjects/Alpaca-Test/venv/lib/python3.8/site-packages/alpaca_trade_api/rest.py", line 234, in _one_request
    resp.raise_for_status()
  File "/Users/xinyaoli/PycharmProjects/Alpaca-Test/venv/lib/python3.8/site-packages/requests/models.py", line 1021, in raise_for_status
    raise HTTPError(http_error_msg, response=self)
requests.exceptions.HTTPError: 403 Client Error: Forbidden for url: https://paper-api.alpaca.markets/v2/orders

During handling of the above exception, another exception occurred:

Traceback (most recent call last):
  File "/Users/xinyaoli/PycharmProjects/Alpaca-Test/main.py", line 104, in grid_trading
    self.api.submit_order(ticker, selling_amount, 'sell', 'market', time_in_force='gtc')
  File "/Users/xinyaoli/PycharmProjects/Alpaca-Test/venv/lib/python3.8/site-packages/alpaca_trade_api/rest.py", line 429, in submit_order
    resp = self.post('/orders', params)
  File "/Users/xinyaoli/PycharmProjects/Alpaca-Test/venv/lib/python3.8/site-packages/alpaca_trade_api/rest.py", line 253, in post
    return self._request('POST', path, data)
  File "/Users/xinyaoli/PycharmProjects/Alpaca-Test/venv/lib/python3.8/site-packages/alpaca_trade_api/rest.py", line 213, in _request
    return self._one_request(method, url, opts, retry)
  File "/Users/xinyaoli/PycharmProjects/Alpaca-Test/venv/lib/python3.8/site-packages/alpaca_trade_api/rest.py", line 242, in _one_request
    raise APIError(error, http_error)
alpaca_trade_api.rest.APIError: insufficient balance for BTC (requested: 0.62935923, available: 0)
2023-04-21 16:03:32,084 - INFO - last trade price is: 27248.55
2023-04-21 16:03:33,393 - ERROR - Sell Order submission failed
Traceback (most recent call last):
  File "/Users/xinyaoli/PycharmProjects/Alpaca-Test/venv/lib/python3.8/site-packages/alpaca_trade_api/rest.py", line 234, in _one_request
    resp.raise_for_status()
  File "/Users/xinyaoli/PycharmProjects/Alpaca-Test/venv/lib/python3.8/site-packages/requests/models.py", line 1021, in raise_for_status
    raise HTTPError(http_error_msg, response=self)
requests.exceptions.HTTPError: 403 Client Error: Forbidden for url: https://paper-api.alpaca.markets/v2/orders

During handling of the above exception, another exception occurred:

Traceback (most recent call last):
  File "/Users/xinyaoli/PycharmProjects/Alpaca-Test/main.py", line 104, in grid_trading
    self.api.submit_order(ticker, selling_amount, 'sell', 'market', time_in_force='gtc')
  File "/Users/xinyaoli/PycharmProjects/Alpaca-Test/venv/lib/python3.8/site-packages/alpaca_trade_api/rest.py", line 429, in submit_order
    resp = self.post('/orders', params)
  File "/Users/xinyaoli/PycharmProjects/Alpaca-Test/venv/lib/python3.8/site-packages/alpaca_trade_api/rest.py", line 253, in post
    return self._request('POST', path, data)
  File "/Users/xinyaoli/PycharmProjects/Alpaca-Test/venv/lib/python3.8/site-packages/alpaca_trade_api/rest.py", line 213, in _request
    return self._one_request(method, url, opts, retry)
  File "/Users/xinyaoli/PycharmProjects/Alpaca-Test/venv/lib/python3.8/site-packages/alpaca_trade_api/rest.py", line 242, in _one_request
    raise APIError(error, http_error)
alpaca_trade_api.rest.APIError: insufficient balance for BTC (requested: 0.62935923, available: 0)
2023-04-21 16:03:33,396 - INFO - last trade price is: 27248.55
2023-04-21 16:03:34,692 - ERROR - Sell Order submission failed
Traceback (most recent call last):
  File "/Users/xinyaoli/PycharmProjects/Alpaca-Test/venv/lib/python3.8/site-packages/alpaca_trade_api/rest.py", line 234, in _one_request
    resp.raise_for_status()
  File "/Users/xinyaoli/PycharmProjects/Alpaca-Test/venv/lib/python3.8/site-packages/requests/models.py", line 1021, in raise_for_status
    raise HTTPError(http_error_msg, response=self)
requests.exceptions.HTTPError: 403 Client Error: Forbidden for url: https://paper-api.alpaca.markets/v2/orders

During handling of the above exception, another exception occurred:

Traceback (most recent call last):
  File "/Users/xinyaoli/PycharmProjects/Alpaca-Test/main.py", line 104, in grid_trading
    self.api.submit_order(ticker, selling_amount, 'sell', 'market', time_in_force='gtc')
  File "/Users/xinyaoli/PycharmProjects/Alpaca-Test/venv/lib/python3.8/site-packages/alpaca_trade_api/rest.py", line 429, in submit_order
    resp = self.post('/orders', params)
  File "/Users/xinyaoli/PycharmProjects/Alpaca-Test/venv/lib/python3.8/site-packages/alpaca_trade_api/rest.py", line 253, in post
    return self._request('POST', path, data)
  File "/Users/xinyaoli/PycharmProjects/Alpaca-Test/venv/lib/python3.8/site-packages/alpaca_trade_api/rest.py", line 213, in _request
    return self._one_request(method, url, opts, retry)
  File "/Users/xinyaoli/PycharmProjects/Alpaca-Test/venv/lib/python3.8/site-packages/alpaca_trade_api/rest.py", line 242, in _one_request
    raise APIError(error, http_error)
alpaca_trade_api.rest.APIError: insufficient balance for BTC (requested: 0.62935923, available: 0)
2023-04-21 16:03:34,693 - INFO - last trade price is: 27248.55
2023-04-21 16:03:35,986 - ERROR - Sell Order submission failed
Traceback (most recent call last):
  File "/Users/xinyaoli/PycharmProjects/Alpaca-Test/venv/lib/python3.8/site-packages/alpaca_trade_api/rest.py", line 234, in _one_request
    resp.raise_for_status()
  File "/Users/xinyaoli/PycharmProjects/Alpaca-Test/venv/lib/python3.8/site-packages/requests/models.py", line 1021, in raise_for_status
    raise HTTPError(http_error_msg, response=self)
requests.exceptions.HTTPError: 403 Client Error: Forbidden for url: https://paper-api.alpaca.markets/v2/orders

During handling of the above exception, another exception occurred:

Traceback (most recent call last):
  File "/Users/xinyaoli/PycharmProjects/Alpaca-Test/main.py", line 104, in grid_trading
    self.api.submit_order(ticker, selling_amount, 'sell', 'market', time_in_force='gtc')
  File "/Users/xinyaoli/PycharmProjects/Alpaca-Test/venv/lib/python3.8/site-packages/alpaca_trade_api/rest.py", line 429, in submit_order
    resp = self.post('/orders', params)
  File "/Users/xinyaoli/PycharmProjects/Alpaca-Test/venv/lib/python3.8/site-packages/alpaca_trade_api/rest.py", line 253, in post
    return self._request('POST', path, data)
  File "/Users/xinyaoli/PycharmProjects/Alpaca-Test/venv/lib/python3.8/site-packages/alpaca_trade_api/rest.py", line 213, in _request
    return self._one_request(method, url, opts, retry)
  File "/Users/xinyaoli/PycharmProjects/Alpaca-Test/venv/lib/python3.8/site-packages/alpaca_trade_api/rest.py", line 242, in _one_request
    raise APIError(error, http_error)
alpaca_trade_api.rest.APIError: insufficient balance for BTC (requested: 0.62935923, available: 0)
2023-04-21 16:03:35,988 - INFO - last trade price is: 27248.55
2023-04-21 16:03:40,861 - ERROR - Sell Order submission failed
Traceback (most recent call last):
  File "/Users/xinyaoli/PycharmProjects/Alpaca-Test/venv/lib/python3.8/site-packages/alpaca_trade_api/rest.py", line 234, in _one_request
    resp.raise_for_status()
  File "/Users/xinyaoli/PycharmProjects/Alpaca-Test/venv/lib/python3.8/site-packages/requests/models.py", line 1021, in raise_for_status
    raise HTTPError(http_error_msg, response=self)
requests.exceptions.HTTPError: 403 Client Error: Forbidden for url: https://paper-api.alpaca.markets/v2/orders

During handling of the above exception, another exception occurred:

Traceback (most recent call last):
  File "/Users/xinyaoli/PycharmProjects/Alpaca-Test/main.py", line 104, in grid_trading
    self.api.submit_order(ticker, selling_amount, 'sell', 'market', time_in_force='gtc')
  File "/Users/xinyaoli/PycharmProjects/Alpaca-Test/venv/lib/python3.8/site-packages/alpaca_trade_api/rest.py", line 429, in submit_order
    resp = self.post('/orders', params)
  File "/Users/xinyaoli/PycharmProjects/Alpaca-Test/venv/lib/python3.8/site-packages/alpaca_trade_api/rest.py", line 253, in post
    return self._request('POST', path, data)
  File "/Users/xinyaoli/PycharmProjects/Alpaca-Test/venv/lib/python3.8/site-packages/alpaca_trade_api/rest.py", line 213, in _request
    return self._one_request(method, url, opts, retry)
  File "/Users/xinyaoli/PycharmProjects/Alpaca-Test/venv/lib/python3.8/site-packages/alpaca_trade_api/rest.py", line 242, in _one_request
    raise APIError(error, http_error)
alpaca_trade_api.rest.APIError: insufficient balance for BTC (requested: 0.62935923, available: 0)
2023-04-21 16:03:40,863 - INFO - last trade price is: 27248.55
2023-04-21 16:03:42,061 - INFO - last trade price is: 27309.39
2023-04-21 16:07:01,161 - ERROR - Sell Order submission failed
Traceback (most recent call last):
  File "/Users/xinyaoli/PycharmProjects/Alpaca-Test/venv/lib/python3.8/site-packages/alpaca_trade_api/rest.py", line 234, in _one_request
    resp.raise_for_status()
  File "/Users/xinyaoli/PycharmProjects/Alpaca-Test/venv/lib/python3.8/site-packages/requests/models.py", line 1021, in raise_for_status
    raise HTTPError(http_error_msg, response=self)
requests.exceptions.HTTPError: 403 Client Error: Forbidden for url: https://paper-api.alpaca.markets/v2/orders

During handling of the above exception, another exception occurred:

Traceback (most recent call last):
  File "/Users/xinyaoli/PycharmProjects/Alpaca-Test/main.py", line 104, in grid_trading
    self.api.submit_order(ticker, selling_amount, 'sell', 'market', time_in_force='gtc')
  File "/Users/xinyaoli/PycharmProjects/Alpaca-Test/venv/lib/python3.8/site-packages/alpaca_trade_api/rest.py", line 429, in submit_order
    resp = self.post('/orders', params)
  File "/Users/xinyaoli/PycharmProjects/Alpaca-Test/venv/lib/python3.8/site-packages/alpaca_trade_api/rest.py", line 253, in post
    return self._request('POST', path, data)
  File "/Users/xinyaoli/PycharmProjects/Alpaca-Test/venv/lib/python3.8/site-packages/alpaca_trade_api/rest.py", line 213, in _request
    return self._one_request(method, url, opts, retry)
  File "/Users/xinyaoli/PycharmProjects/Alpaca-Test/venv/lib/python3.8/site-packages/alpaca_trade_api/rest.py", line 242, in _one_request
    raise APIError(error, http_error)
alpaca_trade_api.rest.APIError: insufficient balance for BTC (requested: 0.629173659, available: 0)
2023-04-21 16:07:01,166 - INFO - last trade price is: 27309.39
2023-04-21 16:07:25,325 - ERROR - Sell Order submission failed
Traceback (most recent call last):
  File "/Users/xinyaoli/PycharmProjects/Alpaca-Test/venv/lib/python3.8/site-packages/alpaca_trade_api/rest.py", line 234, in _one_request
    resp.raise_for_status()
  File "/Users/xinyaoli/PycharmProjects/Alpaca-Test/venv/lib/python3.8/site-packages/requests/models.py", line 1021, in raise_for_status
    raise HTTPError(http_error_msg, response=self)
requests.exceptions.HTTPError: 403 Client Error: Forbidden for url: https://paper-api.alpaca.markets/v2/orders

During handling of the above exception, another exception occurred:

Traceback (most recent call last):
  File "/Users/xinyaoli/PycharmProjects/Alpaca-Test/main.py", line 104, in grid_trading
    self.api.submit_order(ticker, selling_amount, 'sell', 'market', time_in_force='gtc')
  File "/Users/xinyaoli/PycharmProjects/Alpaca-Test/venv/lib/python3.8/site-packages/alpaca_trade_api/rest.py", line 429, in submit_order
    resp = self.post('/orders', params)
  File "/Users/xinyaoli/PycharmProjects/Alpaca-Test/venv/lib/python3.8/site-packages/alpaca_trade_api/rest.py", line 253, in post
    return self._request('POST', path, data)
  File "/Users/xinyaoli/PycharmProjects/Alpaca-Test/venv/lib/python3.8/site-packages/alpaca_trade_api/rest.py", line 213, in _request
    return self._one_request(method, url, opts, retry)
  File "/Users/xinyaoli/PycharmProjects/Alpaca-Test/venv/lib/python3.8/site-packages/alpaca_trade_api/rest.py", line 242, in _one_request
    raise APIError(error, http_error)
alpaca_trade_api.rest.APIError: insufficient balance for BTC (requested: 0.629348999, available: 0)
2023-04-21 16:07:25,329 - INFO - last trade price is: 27309.39
2023-04-21 16:07:26,624 - ERROR - Sell Order submission failed
Traceback (most recent call last):
  File "/Users/xinyaoli/PycharmProjects/Alpaca-Test/venv/lib/python3.8/site-packages/alpaca_trade_api/rest.py", line 234, in _one_request
    resp.raise_for_status()
  File "/Users/xinyaoli/PycharmProjects/Alpaca-Test/venv/lib/python3.8/site-packages/requests/models.py", line 1021, in raise_for_status
    raise HTTPError(http_error_msg, response=self)
requests.exceptions.HTTPError: 403 Client Error: Forbidden for url: https://paper-api.alpaca.markets/v2/orders

During handling of the above exception, another exception occurred:

Traceback (most recent call last):
  File "/Users/xinyaoli/PycharmProjects/Alpaca-Test/main.py", line 104, in grid_trading
    self.api.submit_order(ticker, selling_amount, 'sell', 'market', time_in_force='gtc')
  File "/Users/xinyaoli/PycharmProjects/Alpaca-Test/venv/lib/python3.8/site-packages/alpaca_trade_api/rest.py", line 429, in submit_order
    resp = self.post('/orders', params)
  File "/Users/xinyaoli/PycharmProjects/Alpaca-Test/venv/lib/python3.8/site-packages/alpaca_trade_api/rest.py", line 253, in post
    return self._request('POST', path, data)
  File "/Users/xinyaoli/PycharmProjects/Alpaca-Test/venv/lib/python3.8/site-packages/alpaca_trade_api/rest.py", line 213, in _request
    return self._one_request(method, url, opts, retry)
  File "/Users/xinyaoli/PycharmProjects/Alpaca-Test/venv/lib/python3.8/site-packages/alpaca_trade_api/rest.py", line 242, in _one_request
    raise APIError(error, http_error)
alpaca_trade_api.rest.APIError: insufficient balance for BTC (requested: 0.629348999, available: 0)
2023-04-21 16:07:26,626 - INFO - last trade price is: 27309.39
2023-04-21 16:07:27,927 - ERROR - Sell Order submission failed
Traceback (most recent call last):
  File "/Users/xinyaoli/PycharmProjects/Alpaca-Test/venv/lib/python3.8/site-packages/alpaca_trade_api/rest.py", line 234, in _one_request
    resp.raise_for_status()
  File "/Users/xinyaoli/PycharmProjects/Alpaca-Test/venv/lib/python3.8/site-packages/requests/models.py", line 1021, in raise_for_status
    raise HTTPError(http_error_msg, response=self)
requests.exceptions.HTTPError: 403 Client Error: Forbidden for url: https://paper-api.alpaca.markets/v2/orders

During handling of the above exception, another exception occurred:

Traceback (most recent call last):
  File "/Users/xinyaoli/PycharmProjects/Alpaca-Test/main.py", line 104, in grid_trading
    self.api.submit_order(ticker, selling_amount, 'sell', 'market', time_in_force='gtc')
  File "/Users/xinyaoli/PycharmProjects/Alpaca-Test/venv/lib/python3.8/site-packages/alpaca_trade_api/rest.py", line 429, in submit_order
    resp = self.post('/orders', params)
  File "/Users/xinyaoli/PycharmProjects/Alpaca-Test/venv/lib/python3.8/site-packages/alpaca_trade_api/rest.py", line 253, in post
    return self._request('POST', path, data)
  File "/Users/xinyaoli/PycharmProjects/Alpaca-Test/venv/lib/python3.8/site-packages/alpaca_trade_api/rest.py", line 213, in _request
    return self._one_request(method, url, opts, retry)
  File "/Users/xinyaoli/PycharmProjects/Alpaca-Test/venv/lib/python3.8/site-packages/alpaca_trade_api/rest.py", line 242, in _one_request
    raise APIError(error, http_error)
alpaca_trade_api.rest.APIError: insufficient balance for BTC (requested: 0.629348999, available: 0)
2023-04-21 16:07:27,929 - INFO - last trade price is: 27309.39
2023-04-21 16:07:29,238 - ERROR - Sell Order submission failed
Traceback (most recent call last):
  File "/Users/xinyaoli/PycharmProjects/Alpaca-Test/venv/lib/python3.8/site-packages/alpaca_trade_api/rest.py", line 234, in _one_request
    resp.raise_for_status()
  File "/Users/xinyaoli/PycharmProjects/Alpaca-Test/venv/lib/python3.8/site-packages/requests/models.py", line 1021, in raise_for_status
    raise HTTPError(http_error_msg, response=self)
requests.exceptions.HTTPError: 403 Client Error: Forbidden for url: https://paper-api.alpaca.markets/v2/orders

During handling of the above exception, another exception occurred:

Traceback (most recent call last):
  File "/Users/xinyaoli/PycharmProjects/Alpaca-Test/main.py", line 104, in grid_trading
    self.api.submit_order(ticker, selling_amount, 'sell', 'market', time_in_force='gtc')
  File "/Users/xinyaoli/PycharmProjects/Alpaca-Test/venv/lib/python3.8/site-packages/alpaca_trade_api/rest.py", line 429, in submit_order
    resp = self.post('/orders', params)
  File "/Users/xinyaoli/PycharmProjects/Alpaca-Test/venv/lib/python3.8/site-packages/alpaca_trade_api/rest.py", line 253, in post
    return self._request('POST', path, data)
  File "/Users/xinyaoli/PycharmProjects/Alpaca-Test/venv/lib/python3.8/site-packages/alpaca_trade_api/rest.py", line 213, in _request
    return self._one_request(method, url, opts, retry)
  File "/Users/xinyaoli/PycharmProjects/Alpaca-Test/venv/lib/python3.8/site-packages/alpaca_trade_api/rest.py", line 242, in _one_request
    raise APIError(error, http_error)
alpaca_trade_api.rest.APIError: insufficient balance for BTC (requested: 0.629348557, available: 0)
2023-04-21 16:07:29,239 - INFO - last trade price is: 27309.39
2023-04-21 16:07:30,517 - ERROR - Sell Order submission failed
Traceback (most recent call last):
  File "/Users/xinyaoli/PycharmProjects/Alpaca-Test/venv/lib/python3.8/site-packages/alpaca_trade_api/rest.py", line 234, in _one_request
    resp.raise_for_status()
  File "/Users/xinyaoli/PycharmProjects/Alpaca-Test/venv/lib/python3.8/site-packages/requests/models.py", line 1021, in raise_for_status
    raise HTTPError(http_error_msg, response=self)
requests.exceptions.HTTPError: 403 Client Error: Forbidden for url: https://paper-api.alpaca.markets/v2/orders

During handling of the above exception, another exception occurred:

Traceback (most recent call last):
  File "/Users/xinyaoli/PycharmProjects/Alpaca-Test/main.py", line 104, in grid_trading
    self.api.submit_order(ticker, selling_amount, 'sell', 'market', time_in_force='gtc')
  File "/Users/xinyaoli/PycharmProjects/Alpaca-Test/venv/lib/python3.8/site-packages/alpaca_trade_api/rest.py", line 429, in submit_order
    resp = self.post('/orders', params)
  File "/Users/xinyaoli/PycharmProjects/Alpaca-Test/venv/lib/python3.8/site-packages/alpaca_trade_api/rest.py", line 253, in post
    return self._request('POST', path, data)
  File "/Users/xinyaoli/PycharmProjects/Alpaca-Test/venv/lib/python3.8/site-packages/alpaca_trade_api/rest.py", line 213, in _request
    return self._one_request(method, url, opts, retry)
  File "/Users/xinyaoli/PycharmProjects/Alpaca-Test/venv/lib/python3.8/site-packages/alpaca_trade_api/rest.py", line 242, in _one_request
    raise APIError(error, http_error)
alpaca_trade_api.rest.APIError: insufficient balance for BTC (requested: 0.629348557, available: 0)
2023-04-21 16:07:30,518 - INFO - last trade price is: 27309.39
2023-04-21 16:07:31,810 - ERROR - Sell Order submission failed
Traceback (most recent call last):
  File "/Users/xinyaoli/PycharmProjects/Alpaca-Test/venv/lib/python3.8/site-packages/alpaca_trade_api/rest.py", line 234, in _one_request
    resp.raise_for_status()
  File "/Users/xinyaoli/PycharmProjects/Alpaca-Test/venv/lib/python3.8/site-packages/requests/models.py", line 1021, in raise_for_status
    raise HTTPError(http_error_msg, response=self)
requests.exceptions.HTTPError: 403 Client Error: Forbidden for url: https://paper-api.alpaca.markets/v2/orders

During handling of the above exception, another exception occurred:

Traceback (most recent call last):
  File "/Users/xinyaoli/PycharmProjects/Alpaca-Test/main.py", line 104, in grid_trading
    self.api.submit_order(ticker, selling_amount, 'sell', 'market', time_in_force='gtc')
  File "/Users/xinyaoli/PycharmProjects/Alpaca-Test/venv/lib/python3.8/site-packages/alpaca_trade_api/rest.py", line 429, in submit_order
    resp = self.post('/orders', params)
  File "/Users/xinyaoli/PycharmProjects/Alpaca-Test/venv/lib/python3.8/site-packages/alpaca_trade_api/rest.py", line 253, in post
    return self._request('POST', path, data)
  File "/Users/xinyaoli/PycharmProjects/Alpaca-Test/venv/lib/python3.8/site-packages/alpaca_trade_api/rest.py", line 213, in _request
    return self._one_request(method, url, opts, retry)
  File "/Users/xinyaoli/PycharmProjects/Alpaca-Test/venv/lib/python3.8/site-packages/alpaca_trade_api/rest.py", line 242, in _one_request
    raise APIError(error, http_error)
alpaca_trade_api.rest.APIError: insufficient balance for BTC (requested: 0.629348557, available: 0)
2023-04-21 16:07:31,825 - INFO - last trade price is: 27309.39
2023-04-21 16:07:33,133 - ERROR - Sell Order submission failed
Traceback (most recent call last):
  File "/Users/xinyaoli/PycharmProjects/Alpaca-Test/venv/lib/python3.8/site-packages/alpaca_trade_api/rest.py", line 234, in _one_request
    resp.raise_for_status()
  File "/Users/xinyaoli/PycharmProjects/Alpaca-Test/venv/lib/python3.8/site-packages/requests/models.py", line 1021, in raise_for_status
    raise HTTPError(http_error_msg, response=self)
requests.exceptions.HTTPError: 403 Client Error: Forbidden for url: https://paper-api.alpaca.markets/v2/orders

During handling of the above exception, another exception occurred:

Traceback (most recent call last):
  File "/Users/xinyaoli/PycharmProjects/Alpaca-Test/main.py", line 104, in grid_trading
    self.api.submit_order(ticker, selling_amount, 'sell', 'market', time_in_force='gtc')
  File "/Users/xinyaoli/PycharmProjects/Alpaca-Test/venv/lib/python3.8/site-packages/alpaca_trade_api/rest.py", line 429, in submit_order
    resp = self.post('/orders', params)
  File "/Users/xinyaoli/PycharmProjects/Alpaca-Test/venv/lib/python3.8/site-packages/alpaca_trade_api/rest.py", line 253, in post
    return self._request('POST', path, data)
  File "/Users/xinyaoli/PycharmProjects/Alpaca-Test/venv/lib/python3.8/site-packages/alpaca_trade_api/rest.py", line 213, in _request
    return self._one_request(method, url, opts, retry)
  File "/Users/xinyaoli/PycharmProjects/Alpaca-Test/venv/lib/python3.8/site-packages/alpaca_trade_api/rest.py", line 242, in _one_request
    raise APIError(error, http_error)
alpaca_trade_api.rest.APIError: insufficient balance for BTC (requested: 0.629348557, available: 0)
2023-04-21 16:07:33,136 - INFO - last trade price is: 27309.39
2023-04-21 16:07:47,816 - INFO - buying power is: 171815.13376228517
2023-04-21 16:07:47,816 - INFO - last trade price is: 27309.39
2023-04-21 16:07:47,816 - INFO - holding amount is: 0
